Full Traceback (most recent call last):
  File "/Users/morril01/anaconda3/envs/snakemake-globalDA/lib/python3.6/site-packages/snakemake/io.py", line 794, in expand
    for filepattern in filepatterns
  File "/Users/morril01/anaconda3/envs/snakemake-globalDA/lib/python3.6/site-packages/snakemake/io.py", line 795, in <listcomp>
    for comb in map(dict, combinator(*flatten(wildcards[filepattern])))]
KeyError: 'datasetgeneration'

During handling of the above exception, another exception occurred:

Traceback (most recent call last):
  File "/Users/morril01/anaconda3/envs/snakemake-globalDA/lib/python3.6/site-packages/snakemake/__init__.py", line 401, in snakemake
    print_compilation=print_compilation)
  File "/Users/morril01/anaconda3/envs/snakemake-globalDA/lib/python3.6/site-packages/snakemake/workflow.py", line 743, in include
    exec(compile(code, snakefile, "exec"), self.globals)
  File "/Users/morril01/Documents/PhD/GlobalDA/code/Snakefile", line 447, in <module>
  File "/Users/morril01/anaconda3/envs/snakemake-globalDA/lib/python3.6/site-packages/snakemake/io.py", line 797, in expand
    raise WildcardError("No values given for wildcard {}.".format(e))
snakemake.exceptions.WildcardError: No values given for wildcard 'datasetgeneration'.

WildcardError in line 345 of /Users/morril01/Documents/PhD/GlobalDA/code/Snakefile:
No values given for wildcard 'datasetgeneration'.
  File "/Users/morril01/Documents/PhD/GlobalDA/code/Snakefile", line 345, in <module>
